Workbook

Sheet data gathering
C2: Property | I2: Mining & Oil | O2: Financials
C3: Specifications | I3: Specifications | O3: Specifications
C4: name: | D4: PSE Property Index | I4: name: | J4: PSE Mining & Oil Index | O4: name: | P4: PSE Financials Index
C5: intervals: | D5: weekly | I5: intervals: | J5: weekly | O5: intervals: | P5: weekly
C6: batch: | D6: first | E6: second | I6: batch: | J6: first | K6: second | O6: batch: | P6: first | Q6: second
C7: start: | D7: =DATE(2019,7,1) -> 43647 | E7: =DATE(2019,12,2) -> 43801 | I7: start: | J7: =DATE(2019,7,1) -> 43647 | K7: =DATE(2019,12,2) -> 43801 | O7: start: | P7: =DATE(2019,7,1) -> 43647 | Q7: =DATE(2019,12,2) -> 43801
C8: end: | D8: =DATE(2019,11,25) -> 43794 | E8: =DATE(2020,5,25) -> 43976 | I8: end: | J8: =DATE(2019,11,25) -> 43794 | K8: =DATE(2020,4,27) -> 43948 | O8: end: | P8: =DATE(2019,11,25) -> 43794 | Q8: =DATE(2020,4,27) -> 43948
C9: hyperlink: | D9: https://www.tradingview.com/chart/CRSXnWRx/?symbol=PSE%3APRO | I9: hyperlink: | J9: https://www.tradingview.com/chart/CRSXnWRx/?symbol=PH+MINING+AND+OIL | O9: hyperlink: | P9: https://www.tradingview.com/chart/CRSXnWRx/?symbol=PSE%3AFIN
C10: Batch 1 | E10: Batch 2 | I10: Batch 1 | K10: Batch 2 | O10: Batch 1 | Q10: Batch 2
C11: Dates | D11: closing prices | E11: Dates | F11: Closing Prices | I11: Dates | J11: closing prices | K11: Dates | L11: Closing Prices | O11: Dates | P11: closing prices | Q11: Dates | R11: Closing Prices
C12: =D7+0 -> 43647 | D12: 4379.75 | E12: =E7 -> 43801 | F12: 4099.8799 | I12: =J7+0 -> 43647 | J12: 7439.29 | K12: =K7 -> 43801 | L12: 7517.51 | O12: =P7 -> 43647 | P12: 1742.01 | Q12: =Q7 -> 43801 | R12: 1874.61
C13: =C12+7 -> 43654 | D13: 4423.9302 | E13: =E12+7 -> 43808 | F13: 4193.9399 | I13: =I12+7 -> 43654 | J13: 7437.16 | K13: =K12+7 -> 43808 | L13: 7521.46 | O13: =O12+7 -> 43654 | P13: 1788.79 | Q13: =Q12+7 -> 43808 | R13: 1903.17
C14: =C13+7 -> 43661 | D14: 4423.5698 | E14: =E13+7 -> 43815 | F14: 4139.54 | I14: =I13+7 -> 43661 | J14: 8126.27 | K14: =K13+7 -> 43815 | L14: 7586.74 | O14: =O13+7 -> 43661 | P14: 1877.28 | Q14: =Q13+7 -> 43815 | R14: 1843.16
C15: =C14+7 -> 43668 | D15: 4347.0898 | E15: =E14+7 -> 43822 | F15: 4154.52 | I15: =I14+7 -> 43668 | J15: 7870.97 | K15: =K14+7 -> 43822 | L15: 8091.98 | O15: =O14+7 -> 43668 | P15: 1848.49 | Q15: =Q14+7 -> 43822 | R15: 1863.65
C16: =C15+7 -> 43675 | D16: 4324 | E16: =E15+7 -> 43829 | F16: 4173.6699 | I16: =I15+7 -> 43675 | J16: 8101.47 | K16: =K15+7 -> 43829 | L16: 8020.76 | O16: =O15+7 -> 43675 | P16: 1861.4 | Q16: =Q15+7 -> 43829 | R16: 1844.48
C17: =C16+7 -> 43682 | D17: 4100.02 | E17: =E16+7 -> 43836 | F17: 4112.3398 | I17: =I16+7 -> 43682 | J17: 8152.22 | K17: =K16+7 -> 43836 | L17: 8107.64 | O17: =O16+7 -> 43682 | P17: 1851.6 | Q17: =Q16+7 -> 43836 | R17: 1827.52
C18: =C17+7 -> 43689 | D18: 4036.97 | E18: =E17+7 -> 43843 | F18: 4035.78 | I18: =I17+7 -> 43689 | J18: 8051.19 | K18: =K17+7 -> 43843 | L18: 8143.53 | O18: =O17+7 -> 43689 | P18: 1779.29 | Q18: =Q17+7 -> 43843 | R18: 1846.91
C19: =C18+7 -> 43696 | D19: 4016.6899 | E19: =E18+7 -> 43850 | F19: 3962.3201 | I19: =I18+7 -> 43696 | J19: 8074 | K19: =K18+7 -> 43850 | L19: 7968.19 | O19: =O18+7 -> 43696 | P19: 1827.12 | Q19: =Q18+7 -> 43850 | R19: 1810.37
C20: =C19+7 -> 43703 | D20: 3998 | E20: =E19+7 -> 43857 | F20: 4727.81 | I20: =I19+7 -> 43703 | J20: 8250.52 | K20: =K19+7 -> 43857 | L20: 7663.26 | O20: =O19+7 -> 43703 | P20: 1833.28 | Q20: =Q19+7 -> 43857 | R20: 1724.93
C21: =C20+7 -> 43710 | D21: 4050.97 | E21: =E20+7 -> 43864 | F21: 6281.71 | I21: =I20+7 -> 43710 | J21: 9269.45 | K21: =K20+7 -> 43864 | L21: 7383.47 | O21: =O20+7 -> 43710 | P21: 1804.17 | Q21: =Q20+7 -> 43864 | R21: 1791.09
C22: =C21+7 -> 43717 | D22: 4064.0801 | E22: =E21+7 -> 43871 | F22: 6451.44 | I22: =I21+7 -> 43717 | J22: 9591.46 | K22: =K21+7 -> 43871 | L22: 7058.64 | O22: =O21+7 -> 43717 | P22: 1832.62 | Q22: =Q21+7 -> 43871 | R22: 1738.95
C23: =C22+7 -> 43724 | D23: 3985.76 | E23: =E22+7 -> 43878 | F23: 7086.9 | I23: =I22+7 -> 43724 | J23: 9375.03 | K23: =K22+7 -> 43878 | L23: 7086.9 | O23: =O22+7 -> 43724 | P23: 1786.58 | Q23: =Q22+7 -> 43878 | R23: 1738.92
C24: =C23+7 -> 43731 | D24: 4068.6201 | E24: =E23+7 -> 43885 | F24: 7058.64 | I24: =I23+7 -> 43731 | J24: 8968.4 | K24: =K23+7 -> 43885 | L24: 6451.44 | O24: =O23+7 -> 43731 | P24: 1803.55 | Q24: =Q23+7 -> 43885 | R24: 1605.99
... C33: =C32+7 -> 43794 | D33: 4043.6001 | E33: =E32+7 -> 43948 | F33: 2715.46 | I33: =I32+7 -> 43794 | J33: 8054.07 | K33: =K32+7 -> 43948 | L33: 4708.57 | O33: =O32+7 -> 43794 | P33: 1841.8 | Q33: =Q32+7 -> 43948 | R33: 1188.67
E34: =E33+7 -> 43955 | F34: 2963.6899 | K34: =K33+7 -> 43955 | L34: 4520.85 | Q34: =Q33+7 -> 43955 | R34: 1148.08
E35: =E34+7 -> 43962 | F35: 2838.3999 | K35: =K34+7 -> 43962 | L35: 4505.48 | Q35: =Q34+7 -> 43962 | R35: 1129.4
E36: =E35+7 -> 43969 | F36: 2824.1599 | K36: =K35+7 -> 43969 | L36: 4465.27 | Q36: =Q35+7 -> 43969 | R36: 1102.5
E37: =E36+7 -> 43976 | F37: 2781.1499 | K37: =K36+7 -> 43976 | L37: 4362.72 | Q37: =Q36+7 -> 43976 | R37: 1176.42
C39: Holding Firms | I39: Industrial | O39: Services
C40: Specifications | I40: Specifications | O40: Specifications
C41: name: | D41: PSE Holding Firms Index | I41: name: | J41: PSE Industrial Index | O41: name: | P41: PSE Services Index
C42: intervals: | D42: weekly | I42: intervals: | J42: weekly | O42: intervals: | P42: weekly
C43: batch: | D43: first | E43: second | I43: batch: | J43: first | K43: second | O43: batch: | P43: first | Q43: second
C44: start: | D44: =DATE(2019,7,1) -> 43647 | E44: =DATE(2019,12,2) -> 43801 | I44: start: | J44: =DATE(2019,7,1) -> 43647 | K44: =DATE(2019,12,2) -> 43801 | O44: start: | P44: =DATE(2019,7,1) -> 43647 | Q44: =DATE(2019,12,2) -> 43801
C45: end: | D45: =DATE(2019,11,25) -> 43794 | E45: =DATE(2020,4,27) -> 43948 | I45: end: | J45: =DATE(2019,11,25) -> 43794 | K45: =DATE(2020,4,27) -> 43948 | O45: end: | P45: =DATE(2019,11,25) -> 43794 | Q45: =DATE(2020,5,25) -> 43976
C46: hyperlink: | D46: https://www.tradingview.com/chart/CRSXnWRx/?symbol=PSE%3AHDG | I46: hyperlink: | J46: https://www.tradingview.com/chart/CRSXnWRx/?symbol=PSE%3AIND | O46: hyperlink: | P46: https://www.tradingview.com/chart/?symbol=PSE%3ASVC
C47: Batch 1 | E47: Batch 2 | I47: Batch 1 | K47: Batch 2 | O47: Batch 1 | Q47: Batch 2
C48: Dates | D48: closing prices | E48: Dates | F48: Closing Prices | I48: Dates | J48: closing prices | K48: Dates | L48: Closing Prices | O48: Dates | P48: closing prices | Q48: Dates | R48: Closing Prices
C49: =D44 -> 43647 | D49: 7797.21 | E49: =E44 -> 43801 | F49: 7750.8198 | I49: =J44 -> 43647 | J49: 11988.32 | K49: =K44 -> 43801 | L49: 9555.4297 | O49: =P44 -> 43647 | P49: 1695.66 | Q49: =Q44 -> 43801 | R49: 1499.35
C50: =C49+7 -> 43654 | D50: 7758.23 | E50: =E49+7 -> 43808 | F50: 7633.3101 | I50: =I49+7 -> 43654 | J50: 11791.25 | K50: =K49+7 -> 43808 | L50: 9722.0801 | O50: =O49+7 -> 43654 | P50: 1693.65 | Q50: =Q49+7 -> 43808 | R50: 1525.19
...

Sheet non data gathering
B2: Correlation Matrix First Batch | J2: batch a edges rankings highest to lowest correlation | O2: batch b edges rankings highest to lowest correlation | T2: Correlation Coefficient | AF2: numerator | AG2: a | AH2: b | AI2: denominator | AJ2: p
C3: Property | D3: Mining & oil | E3: Financials | F3: Holding Firms | G3: Industrial | H3: Services | K3: Pairs or Edge | P3: Pairs or Edge | T3: Pairs | V3: Y_i | W3: Y_j | X3: Y_i * Y_j | Y3: sumate Y_i | Z3: sumate Y_j | AA3: sumate Y_i * Y_j | AB3: sumate Y_i * sumate Y_j | AC3: n | AD3: sumate (Y_i^2) | AE3: sumate (Y_j ^2) | AF3: n (sumate Y_i * Y_j) - sumate Y_i * sumate Y_j | AG3: n(sumate(Y_i^2)) - (sumate_Y_i)^2 | AH3: n(sumate(Y_j^2)) - (sumate_Y_j)^2 | AI3: sqrt(a * b) | AJ3: numerator / denominator
B4: Property | C4: 1 | D4: =AJ4 -> 0.28960107 | E4: =AJ51 -> 0.40029071 | F4: =AJ98 -> 0.42726812 | G4: =AJ145 -> 0.44799204 | H4: =AJ192 -> 0.20644877 | J4: ranking | K4: Y_i | L4: Y_j | M4: Correlation | O4: ranking | P4: Y_i | Q4: Y_j | R4: Correlation | T4: Property | U4: Mining & Oil | V4: {='Data Gathering and ect'!F11:F31} -> 0.010036841 | W4: {='Data Gathering and ect'!F74:F94} -> -0.00028635864 | X4: =PRODUCT(V4:W4) -> -2.8741363e-06 | Y4: =SUM(V4:V24) -> -0.079856236 | Z4: =SUM(W4:W24) -> 0.07940214 | AA4: =SUM(X4:X24) -> 0.004045463 | AB4: =Y4*Z4 -> -0.006340756 | AC4: =COUNT(V4:V24) -> 21 | AD4: {=SUM(POWER(V4:V24,2))} -> 0.0063412952 | AE4: {=SUM(POWER(W4:W24,2))} -> 0.037624664 | AF4: =(AA4*AC4)-(AB4) -> 0.091295479 | AG4: =(AC4*AD4)-(POWER(Y4,2)) -> 0.12679018 | AH4: =(AC4*AE4)-(POWER(Z4,2)) -> 0.78381324 | AI4: =SQRT(AG4*AH4) -> 0.31524566 | AJ4: =AF4 / AI4 -> 0.28960107
B5: Mining & Oil | C5: =AJ4 -> 0.28960107 | D5: 1 | E5: =AJ239 -> 0.3837013 | F5: =AJ286 -> 0.36093652 | G5: =AJ333 -> 0.22685594 | H5: =AJ380 -> 0.061082877 | J5: 1 | K5: Holding Firms | L5: Industrial | M5: =G7 -> 0.70019825 | O5: 1 | P5: Property | Q5: Holding Firms | R5: =F13 -> 0.91998968 | V5: -8.1469342e-05 | W5: 0.088612968 | X5: =PRODUCT(V5:W5) -> -7.2192402e-06
B6: Financials | C6: =AJ51 -> 0.40029071 | D6: =AJ239 -> 0.3837013 | E6: 1 | F6: =AJ427 -> 0.35345537 | G6: =AJ474 -> 0.23885045 | H6: =AJ521 -> 0.32336999 | J6: 2 | K6: Industrial | L6: Services | M6: =H8 -> 0.51545111 | O6: 2 | P6: Financials | Q6: Holding Firms | R6: =F15 -> 0.89815001 | V6: -0.017440407 | W6: -0.031920716 | X6: =PRODUCT(V6:W6) -> 0.00055671029
B7: Holding Firms | C7: =AJ98 -> 0.42726812 | D7: =AJ286 -> 0.36093652 | E7: =AJ427 -> 0.35345537 | F7: 1 | G7: =AJ568 -> 0.70019825 | H7: =AJ615 -> 0.49279386 | J7: 3 | K7: Holding Firms | L7: Services | M7: =H7 -> 0.49279386 | O7: 3 | P7: Holding Firms | Q7: Services | R7: =H16 -> 0.89351158 | V7: -0.0053257099 | W7: 0.028864219 | X7: =PRODUCT(V7:W7) -> -0.00015372246
B8: Industrial | C8: =AJ145 -> 0.44799204 | D8: =AJ333 -> 0.22685594 | E8: =AJ474 -> 0.23885045 | F8: =AJ568 -> 0.70019825 | G8: 1 | H8: =AJ662 -> 0.51545111 | J8: 4 | K8: Property | L8: Industrial | M8: =G4 -> 0.44799204 | O8: 4 | P8: Mining & Oil | Q8: Services | R8: =H14 -> 0.87683838 | V8: -0.053189048 | W8: 0.0062447561 | X8: =PRODUCT(V8:W8) -> -0.00033215263
B9: Services | C9: =AJ192 -> 0.20644877 | D9: =AJ380 -> 0.061082877 | E9: =AJ521 -> 0.32336999 | F9: =AJ615 -> 0.49279386 | G9: =AJ662 -> 0.51545111 | H9: 1 | J9: 5 | K9: Property | L9: Holding Firms | M9: =F4 -> 0.42726812 | O9: 5 | P9: Property | Q9: Services | R9: =H13 -> 0.87316343 | V9: -0.015497441 | W9: -0.012470376 | X9: =PRODUCT(V9:W9) -> 0.00019325892
J10: 6 | K10: Property | L10: Financials | M10: =E4 -> 0.40029071 | O10: 6 | P10: Property | Q10: Mining & Oil | R10: =D13 -> 0.86842976 | V10: -0.0050362551 | W10: 0.0028291158 | X10: =PRODUCT(V10:W10) -> -1.4248149e-05
B11: Correlation Matrix Second Batch | J11: 7 | K11: Mining & Oil | L11: Financials | M11: =E5 -> 0.3837013 | O11: 7 | P11: Property | Q11: Financials | R11: =E13 -> 0.84360101 | V11: -0.0046639194 | W11: 0.021627206 | X11: =PRODUCT(V11:W11) -> -0.00010086755
C12: Property | D12: Mining & oil | E12: Financials | F12: Holding Firms | G12: Industrial | H12: Services | J12: 8 | K12: Mining & Oil | L12: Holding Firms | M12: =F6 -> 0.35345537 | O12: 8 | P12: Financials | Q12: Services | R12: =H15 -> 0.83781277 | V12: 0.013162123 | W12: 0.11644782 | X12: =PRODUCT(V12:W12) -> 0.0015327004
B13: Property | C13: 1 | D13: =AJ25 -> 0.86842976 | E13: =AJ72 -> 0.84360101 | F13: =AJ119 -> 0.91998968 | G13: =AJ166 -> 0.80705694 | H13: =AJ213 -> 0.87316343 | J13: 9 | K13: Financials | L13: Holding Firms | M13: =F5 -> 0.36093652 | O13: 9 | P13: Mining & Oil | Q13: Holding Firms | R13: =F14 -> 0.83416504 | V13: 0.0032310611 | W13: 0.034149073 | X13: =PRODUCT(V13:W13) -> 0.00011033774
B14: Mining & Oil | C14: =AJ25 -> 0.86842976 | D14: 1 | E14: =AJ260 -> 0.79253145 | F14: =AJ307 -> 0.83416504 | G14: =AJ354 -> 0.81297625 | H14: =AJ401 -> 0.87683838 | J14: 10 | K14: Financials | L14: Services | M14: =H4 -> 0.20644877 | O14: 10 | P14: Holding Firms | Q14: Industrial | R14: =G16 -> 0.82958244 | V14: -0.01945941 | W14: -0.022823347 | X14: =PRODUCT(V14:W14) -> 0.00044412889
B15: Financials | C15: =AJ72 -> 0.84360101 | D15: =AJ260 -> 0.79253145 | E15: 1 | F15: =AJ448 -> 0.89815001 | G15: =AJ495 -> 0.7919477 | H15: =AJ542 -> 0.83781277 | J15: 11 | K15: Property | L15: Mining & Oil | M15: =D4 -> 0.28960107 | O15: 11 | P15: Mining & Oil | Q15: Industrial | R15: =G14 -> 0.81297625 | V15: 0.020575891 | W15: -0.044342484 | X15: =PRODUCT(V15:W15) -> -0.00091238612
B16: Holding Firms | C16: =AJ119 -> 0.91998968 | D16: =AJ307 -> 0.83416504 | E16: =AJ448 -> 0.89815001 | F16: 1 | G16: =AJ589 -> 0.82958244 | H16: =AJ636 -> 0.89351158 | J16: 12 | K16: Financials | L16: Industrial | M16: =G6 -> 0.23885045 | O16: 12 | P16: Industrial | Q16: Services | R16: =H17 -> 0.81093903 | V16: -0.01428827 | W16: -0.014073186 | X16: =PRODUCT(V16:W16) -> 0.00020108149
B17: Industrial | C17: =AJ166 -> 0.80705694 | D17: =AJ354 -> 0.81297625 | E17: =AJ495 -> 0.7919477 | F17: =AJ589 -> 0.82958244 | G17: 1 | H17: =AJ683 -> 0.81093903 | J17: 13 | K17: Mining & Oil | L17: Industrial | M17: =G5 -> 0.22685594 | O17: 13 | P17: Property | Q17: Industrial | R17: =G13 -> 0.80705694 | V17: 0.02918434 | W17: 0.037214438 | X17: =PRODUCT(V17:W17) -> 0.0010860788
B18: Services | C18: =AJ213 -> 0.87316343 | D18: =AJ401 -> 0.87683838 | E18: =AJ542 -> 0.83781277 | F18: =AJ636 -> 0.89351158 | G18: =AJ683 -> 0.81093903 | H18: 1 | J18: 14 | K18: Property | L18: Services | M18: =H4 -> 0.20644877 | O18: 14 | P18: Mining & Oil | Q18: Financials | R18: =E14 -> 0.79253145 | V18: 0.011453165 | W18: -0.029971761 | X18: =PRODUCT(V18:W18) -> -0.00034327151
J19: 15 | K19: Mining & Oil | L19: Services | M19: =H5 -> 0.061082877 | O19: 15 | P19: Financials | Q19: Industrial | R19: =G14 -> 0.81297625 | V19: -0.0026271837 | W19: 0.033329463 | X19: =PRODUCT(V19:W19) -> -8.7562624e-05
B20: Distance Matrix First Batch | V20: 0.0014390942 | W20: 0.00079128398 | X20: =PRODUCT(V20:W20) -> 1.1387322e-06
C21: Property | D21: Mining & oil | E21: Financials | F21: Holding Firms | G21: Industrial | H21: Services | V21: -0.00033557948 | W21: -0.01353553 | X21: =PRODUCT(V21:W21) -> 4.5422462e-06
B22: Property | C22: 0 | D22: =SQRT(2 * (1 - D4)) -> 1.1919723 | E22: =SQRT(2 * (1 - E4)) -> 1.0951797 | F22: =SQRT(2 * (1 - F4)) -> 1.0702634 | G22: =SQRT(2 * (1 - G4)) -> 1.0507216 | H22: =SQRT(2 * (1 - H4)) -> 1.2598025 | J22: Distance delta stability ranking | V22: -0.012315187 | W22: -0.039306985 | X22: =PRODUCT(V22:W22) -> 0.00048407287
B23: Mining & Oil | C23: =SQRT(2 * (1 - C5)) -> 1.1919723 | D23: 0 | E23: =SQRT(2 * (1 - E5)) -> 1.110224 | F23: =SQRT(2 * (1 - F5)) -> 1.1305428 | G23: =SQRT(2 * (1 - G5)) -> 1.2434983 | H23: =SQRT(2 * (1 - H5)) -> 1.3703409 | K23: Pairs or Edge | M23: Batches | O23: Distance delta | V23: -0.021249215 | W23: -0.067021696 | X23: =PRODUCT(V23:W23) -> 0.0014241584
B24: Financials | C24: =SQRT(2 * (1 - C6)) -> 1.0951797 | D24: =SQRT(2 * (1 - D6)) -> 1.110224 | E24: 0 | F24: =SQRT(2 * (1 - F6)) -> 1.1371408 | G24: =SQRT(2 * (1 - G6)) -> 1.2338149 | H24: =SQRT(2 * (1 - H6)) -> 1.163297 | J24: ranking | K24: Y_i | L24: Y_j | M24: 1st | N24: 2nd | O24: 2nd - 1st | V24: 0.0025703447 | W24: -0.014955761 | X24: =PRODUCT(V24:W24) -> -3.8441461e-05
B25: Holding Firms | C25: =SQRT(2 * (1 - C7)) -> 1.0702634 | D25: =SQRT(2 * (1 - D7)) -> 1.1305428 | E25: =SQRT(2 * (1 - E7)) -> 1.1371408 | F25: 0 | G25: =SQRT(2 * (1 - G7)) -> 0.77434069 | H25: =SQRT(2 * (1 - H7)) -> 1.0071804 | J25: 1 | K25: Holding Firms | L25: Industrial | M25: =G25 -> 0.77434069 | N25: =G34 -> 0.58381085 | O25: =N25-M25 -> -0.19052984 | V25: {='Data Gathering and ect'!F32:F57} -> 0.013822272 | W25: {='Data Gathering and ect'!F95:F120} -> -0.068942588 | X25: =PRODUCT(V25:W25) -> -0.00095294317 | Y25: =SUM(V25:V50) -> -0.37256446 | Z25: =SUM(W25:W50) -> -0.61308184 | AA25: =SUM(X25:X50) -> 0.13029892 | AB25: =Y25*Z25 -> 0.22841251 | AC25: =COUNT(V25:V50) -> 26 | AD25: {=SUM(POWER(V25:V50,2))} -> 0.12426486 | AE25: {=SUM(POWER(W25:W50,2))} -> 0.17908473 | AF25: =(AA25*AC25)-(AB25) -> 3.1593593 | AG25: =(AC25*AD25)-(POWER(Y25,2)) -> 3.0920821 | AH25: =(AC25*AE25)-(POWER(Z25,2)) -> 4.2803337 | AI25: =SQRT(AG25*AH25) -> 3.6380136 | AJ25: =AF25 / AI25 -> 0.86842976
B26: Industrial | C26: =SQRT(2 * (1 - C8)) -> 1.0507216 | D26: =SQRT(2 * (1 - D8)) -> 1.2434983 | E26: =SQRT(2 * (1 - E8)) -> 1.2338149 | F26: =SQRT(2 * (1 - F8)) -> 0.77434069 | G26: 0 | H26: =SQRT(2 * (1 - H8)) -> 0.98442765 | J26: 2 | K26: Industrial | L26: Services | M26: =H26 -> 0.98442765 | N26: =H35 -> 0.6149162 | O26: =N26-M26 -> -0.36951145 | V26: 0.022682922 | W26: 0.00052530194 | X26: =PRODUCT(V26:W26) -> 1.1915383e-05
B27: Services | C27: =SQRT(2 * (1 - C9)) -> 1.2598025 | D27: =SQRT(2 * (1 - D9)) -> 1.3703409 | E27: =SQRT(2 * (1 - E9)) -> 1.163297 | F27: =SQRT(2 * (1 - F9)) -> 1.0071804 | G27: =SQRT(2 * (1 - G9)) -> 0.98442765 | H27: 0 | J27: 3 | K27: Property | L27: Industrial | M27: =G22 -> 1.0507216 | N27: =G31 -> 0.62119733 | O27: =N27-M27 -> -0.42952429 | V27: -0.013055932 | W27: 0.0086417186 | X27: =PRODUCT(V27:W27) -> -0.00011282569
J28: 4 | K28: Mining & Oil | L28: Financials | M28: =E23 -> 1.110224 | N28: =E32 -> 0.64415611 | O28: =N28-M28 -> -0.46606792 | V28: 0.0036122276 | W28: 0.064471461 | X28: =PRODUCT(V28:W28) -> 0.00023288559
B29: Distance Matrix Second Batch | J29: 5 | K29: Property | L29: Financials | M29: =E22 -> 1.0951797 | N29: =E31 -> 0.55928346 | O29: =N29-M29 -> -0.53589625 | V29: 0.0045988225 | W29: -0.0088402672 | X29: =PRODUCT(V29:W29) -> -4.065482e-05
C30: Property | D30: Mining & oil | E30: Financials | F30: Holding Firms | G30: Industrial | H30: Services | J30: 6 | K30: Holding Firms | L30: Services | M30: =H25 -> 1.0071804 | N30: =H34 -> 0.46149413 | O30: =N30-M30 -> -0.54568623 | V30: -0.01480356 | W30: 0.010773647 | X30: =PRODUCT(V30:W30) -> -0.00015948832
B31: Property | C31: 0 | D31: =SQRT(2 * (1 - D13)) -> 0.51297219 | E31: =SQRT(2 * (1 - E13)) -> 0.55928346 | F31: =SQRT(2 * (1 - F13)) -> 0.4000258 | G31: =SQRT(2 * (1 - G13)) -> 0.62119733 | H31: =SQRT(2 * (1 - H13)) -> 0.50365975 | J31: 7 | K31: Mining & Oil | L31: Holding Firms | M31: =F23 -> 1.1305428 | N31: =F32 -> 0.57590791 | O31: =N31-M31 -> -0.55463486 | V31: -0.018792569 | W31: 0.0044169199 | X31: =PRODUCT(V31:W31) -> -8.3005274e-05
B32: Mining & Oil | C32: =SQRT(2 * (1 - C14)) -> 0.51297219 | D32: 0 | E32: =SQRT(2 * (1 - E14)) -> 0.64415611 | F32: =SQRT(2 * (1 - F14)) -> 0.57590791 | G32: =SQRT(2 * (1 - G14)) -> 0.61159422 | H32: =SQRT(2 * (1 - H14)) -> 0.49630963 | J32: 8 | K32: Financials | L32: Industrial | M32: =G24 -> 1.2338149 | N32: =G33 -> 0.64506171 | O32: =N32-M32 -> -0.58875315 | V32: -0.018369854 | W32: -0.021766382 | X32: =PRODUCT(V32:W32) -> 0.00039984525
B33: Financials | C33: =SQRT(2 * (1 - C15)) -> 0.55928346 | D33: =SQRT(2 * (1 - D15)) -> 0.64415611 | E33: 0 | F33: =SQRT(2 * (1 - F15)) -> 0.45133135 | G33: =SQRT(2 * (1 - G15)) -> 0.64506171 | H33: =SQRT(2 * (1 - H15)) -> 0.56953882 | J33: 9 | K33: Financials | L33: Services | M33: =H24 -> 1.163297 | N33: =H33 -> 0.56953882 | O33: =N33-M33 -> -0.59375823 | V33: -0.03168555 | W33: -0.039019885 | X33: =PRODUCT(V33:W33) -> 0.0012363665
B34: Holding Firms | C34: =SQRT(2 * (1 - C16)) -> 0.4000258 | D34: =SQRT(2 * (1 - D16)) -> 0.57590791 | E34: =SQRT(2 * (1 - E16)) -> 0.45133135 | F34: 0 | G34: =SQRT(2 * (1 - G16)) -> 0.58381085 | H34: =SQRT(2 * (1 - H16)) -> 0.46149413 | J34: 10 | K34: Mining & Oil | L34: Industrial | M34: =G23 -> 1.2434983 | N34: =G32 -> 0.61159422 | O34: =N34-M34 -> -0.63190412 | V34: 0.050308111 | W34: -0.037193763 | X34: =PRODUCT(V34:W34) -> -0.001871148
B35: Industrial | C35: =SQRT(2 * (1 - C17)) -> 0.62119733 | D35: =SQRT(2 * (1 - D17)) -> 0.61159422 | E35: =SQRT(2 * (1 - E17)) -> 0.64506171 | F35: =SQRT(2 * (1 - F17)) -> 0.58381085 | G35: 0 | H35: =SQRT(2 * (1 - H17)) -> 0.6149162 | J35: 11 | K35: Property | L35: Holding Firms | M35: =F22 -> 1.0702634 | N35: =F31 -> 0.4000258 | O35: =N35-M35 -> -0.67023761 | V35: -0.027156469 | W35: -0.044991319 | X35: =PRODUCT(V35:W35) -> 0.0012218054
B36: Services | C36: =SQRT(2 * (1 - C18)) -> 0.50365975 | D36: =SQRT(2 * (1 - D18)) -> 0.49630963 | E36: =SQRT(2 * (1 - E18)) -> 0.56953882 | F36: =SQRT(2 * (1 - F18)) -> 0.46149413 | G36: =SQRT(2 * (1 - G18)) -> 0.6149162 | H36: 0 | J36: 12 | K36: Property | L36: Mining & Oil | M36: =D22 -> 1.1919723 | N36: =D31 -> 0.51297219 | O36: =N36-M36 -> -0.67900006 | V36: 0.004089751 | W36: 0.003995611 | X36: =PRODUCT(V36:W36) -> 1.6341054e-05
J37: 13 | K37: Financials | L37: Holding Firms | M37: =F23 -> 1.1305428 | N37: =F33 -> 0.45133135 | O37: =N37-M37 -> -0.67921143 | V37: -0.082277311 | W37: -0.093944648 | X37: =PRODUCT(V37:W37) -> 0.007729513
J38: 14 | K38: Property | L38: Services | M38: =H22 -> 1.2598025 | N38: =H31 -> 0.50365975 | O38: =N38-M38 -> -0.75614279 | V38: 0.014127004 | W38: -0.026661125 | X38: =PRODUCT(V38:W38) -> -0.00037664182
J39: 15 | K39: Mining & Oil | L39: Services | M39: =H23 -> 1.3703409 | N39: =H35 -> 0.6149162 | O39: =N39-M39 -> -0.75542472 | V39: -0.21050157 | W39: -0.28418014 | X39: =PRODUCT(V39:W39) -> 0.059820365
V40: -0.19019186 | W40: -0.23291498 | X40: =PRODUCT(V40:W40) -> 0.044298534
J41: Correlation delta stability ranking | V41: 0.11932263 | W41: 0.091042122 | X41: =PRODUCT(V41:W41) -> 0.010863385
...

Sheet Data Gathering and ect
B1: Property
B2: Specifications
B3: name: | C3: PSE Property Index
B4: intervals: | C4: weekly
B5: batch: | C5: first | D5: second
B6: start: | C6: =DATE(2019,7,1) -> 43647 | D6: =DATE(2019,12,2) -> 43801
B7: end: | C7: =DATE(2019,11,25) -> 43794 | D7: =DATE(2020,5,25) -> 43976
B8: hyperlink: | C8: https://www.tradingview.com/chart/CRSXnWRx/?symbol=PSE%3APRO
B9: Dates | C9: closing prices | D9: log pt-1 | E9: logpt | F9: log pt - log pt-1
B10: =C6+0 -> 43647 | C10: 4379.75 | D10: =LN(C10) -> 8.3847469
B11: =B10+7 -> 43654 | C11: 4423.9302 | D11: =LN(C11) -> 8.3947838 | E11: =LN(C11) -> 8.3947838 | F11: =E11-D10 -> 0.010036841
B12: =B11+7 -> 43661 | C12: 4423.5698 | D12: =LN(C12) -> 8.3947023 | E12: =LN(C12) -> 8.3947023 | F12: =E12-D11 -> -8.1469342e-05
B13: =B12+7 -> 43668 | C13: 4347.0898 | D13: =LN(C13) -> 8.3772619 | E13: =LN(C13) -> 8.3772619 | F13: =E13-D12 -> -0.017440407
B14: =B13+7 -> 43675 | C14: 4324 | D14: =LN(C14) -> 8.3719362 | E14: =LN(C14) -> 8.3719362 | F14: =E14-D13 -> -0.0053257099
B15: =B14+7 -> 43682 | C15: 4100.02 | D15: =LN(C15) -> 8.3187471 | E15: =LN(C15) -> 8.3187471 | F15: =E15-D14 -> -0.053189048
B16: =B15+7 -> 43689 | C16: 4036.97 | D16: =LN(C16) -> 8.3032497 | E16: =LN(C16) -> 8.3032497 | F16: =E16-D15 -> -0.015497441
B17: =B16+7 -> 43696 | C17: 4016.6899 | D17: =LN(C17) -> 8.2982134 | E17: =LN(C17) -> 8.2982134 | F17: =E17-D16 -> -0.0050362551
B18: =B17+7 -> 43703 | C18: 3998 | D18: =LN(C18) -> 8.2935495 | E18: =LN(C18) -> 8.2935495 | F18: =E18-D17 -> -0.0046639194
B19: =B18+7 -> 43710 | C19: 4050.97 | D19: =LN(C19) -> 8.3067116 | E19: =LN(C19) -> 8.3067116 | F19: =E19-D18 -> 0.013162123
B20: =B19+7 -> 43717 | C20: 4064.0801 | D20: =LN(C20) -> 8.3099427 | E20: =LN(C20) -> 8.3099427 | F20: =E20-D19 -> 0.0032310611
B21: =B20+7 -> 43724 | C21: 3985.76 | D21: =LN(C21) -> 8.2904833 | E21: =LN(C21) -> 8.2904833 | F21: =E21-D20 -> -0.01945941
B22: =B21+7 -> 43731 | C22: 4068.6201 | D22: =LN(C22) -> 8.3110592 | E22: =LN(C22) -> 8.3110592 | F22: =E22-D21 -> 0.020575891
... B31: =B30+7 -> 43794 | C31: 4043.6001 | D31: =LN(C31) -> 8.3048907 | E31: =LN(C31) -> 8.3048907 | F31: =E31-D30 -> 0.0025703447
B32: =D6 -> 43801 | C32: 4099.8799 | D32: =LN(C32) -> 8.318713 | E32: =LN(C32) -> 8.318713 | F32: =E32-D31 -> 0.013822272
B33: =B32+7 -> 43808 | C33: 4193.9399 | D33: =LN(C33) -> 8.3413959 | E33: =LN(C33) -> 8.3413959 | F33: =E33-D32 -> 0.022682922
B34: =B33+7 -> 43815 | C34: 4139.54 | D34: =LN(C34) -> 8.3283399 | E34: =LN(C34) -> 8.3283399 | F34: =E34-D33 -> -0.013055932
B35: =B34+7 -> 43822 | C35: 4154.52 | D35: =LN(C35) -> 8.3319522 | E35: =LN(C35) -> 8.3319522 | F35: =E35-D34 -> 0.0036122276
B36: =B35+7 -> 43829 | C36: 4173.6699 | D36: =LN(C36) -> 8.336551 | E36: =LN(C36) -> 8.336551 | F36: =E36-D35 -> 0.0045988225
B37: =B36+7 -> 43836 | C37: 4112.3398 | D37: =LN(C37) -> 8.3217474 | E37: =LN(C37) -> 8.3217474 | F37: =E37-D36 -> -0.01480356
B38: =B37+7 -> 43843 | C38: 4035.78 | D38: =LN(C38) -> 8.3029549 | E38: =LN(C38) -> 8.3029549 | F38: =E38-D37 -> -0.018792569
B39: =B38+7 -> 43850 | C39: 3962.3201 | D39: =LN(C39) -> 8.284585 | E39: =LN(C39) -> 8.284585 | F39: =E39-D38 -> -0.018369854
B40: =B39+7 -> 43857 | C40: 3838.74 | D40: =LN(C40) -> 8.2528995 | E40: =LN(C40) -> 8.2528995 | F40: =E40-D39 -> -0.03168555
B41: =B40+7 -> 43864 | C41: 4036.8 | D41: =LN(C41) -> 8.3032076 | E41: =LN(C41) -> 8.3032076 | F41: =E41-D40 -> 0.050308111
B42: =B41+7 -> 43871 | C42: 3928.6499 | D42: =LN(C42) -> 8.2760511 | E42: =LN(C42) -> 8.2760511 | F42: =E42-D41 -> -0.027156469
B43: =B42+7 -> 43878 | C43: 3944.75 | D43: =LN(C43) -> 8.2801409 | E43: =LN(C43) -> 8.2801409 | F43: =E43-D42 -> 0.004089751
B44: =B43+7 -> 43885 | C44: 3633.1799 | D44: =LN(C44) -> 8.1978635 | E44: =LN(C44) -> 8.1978635 | F44: =E44-D43 -> -0.082277311
... B56: =B55+7 -> 43969 | C56: 2815.6499 | D56: =LN(C56) -> 7.9429484 | E56: =LN(C56) -> 7.9429484 | F56: =E56-D55 -> -0.0080473726
B57: =B56+7 -> 43976 | C57: 2785.8999 | E57: =LN(C57) -> 7.9323262 | F57: =E57-D56 -> -0.01062216
B64: Mining & Oil
B65: Specifications
...
